<mujoco model="xarm_gripper">
  <asset>
    <mesh name="base_link" file="meshes/xarm_gripper/base_link.STL"/>
    <mesh name="base_link_collision" file="meshes/xarm_gripper/base_link_collision.STL"/>
    <mesh name="left_outer_knuckle" file="meshes/xarm_gripper/left_outer_knuckle.STL"/>
    <mesh name="left_finger" file="meshes/xarm_gripper/left_finger.STL"/>
    <mesh name="left_inner_knuckle" file="meshes/xarm_gripper/left_inner_knuckle.STL"/>
    <mesh name="right_outer_knuckle" file="meshes/xarm_gripper/right_outer_knuckle.STL"/>
    <mesh name="right_finger" file="meshes/xarm_gripper/right_finger.STL"/>
    <mesh name="right_inner_knuckle" file="meshes/xarm_gripper/right_inner_knuckle.STL"/>
  </asset>

  <tendon>
    <!--finger2 tendons-->
    <fixed name="finger2_12_cpl" range="-1 1" stiffness="0.1" springlength="0.1" limited="true">
      <joint joint="drive_joint"  coef="1"/>
      <joint joint="left_finger_joint"  coef="-3"/>
      <joint joint="left_inner_knuckle_joint"  coef="-1"/>
    </fixed>

    <!--Finger1 tendons-->
    <fixed name="finger1_12_cpl" range="-1 1" stiffness="0.1" springlength="0.1" limited="true">
      <joint joint="right_outer_knuckle_joint"  coef="1"/>
      <joint joint="right_finger_joint"  coef="-3"/>
      <joint joint="right_inner_knuckle_joint"  coef="-1"/>
    </fixed>
  </tendon>

  <actuator>
    <position name='finger_1' ctrllimited="true" kp="2" joint='drive_joint' ctrlrange='0 0.85'/>
    <position name='finger_2' ctrllimited="true" kp="2" joint='right_outer_knuckle_joint' ctrlrange='0 0.85'/>
  </actuator>

  <worldbody>
    <body name="right_gripper" pos="0 0 0" quat="1 0 0 0 ">
      <geom type="mesh" contype="0" conaffinity="0" group="1" density="0" rgba="1 1 1 1" mesh="base_link" name="base_link"/>
      <geom type="mesh" rgba="1 1 1 1" mesh="base_link_collision" name="base_link_collision"/>
      <site name="ft_frame" pos="0 0 0" size="0.01 0.01 0.01" rgba="1 0 0 1" type="sphere" group="1"/>
      <!-- This site was added for visualization. -->
      <!-- Need to tune grip site -->
      <body name="eef" pos="0 0 0.15" quat="1 0 0 0">
        <site name="grip_site" pos="0 0 0" size="0.01 0.01 0.01" rgba="1 0 0 0.5" type="sphere" group="1"/>
        <site name="ee_x" pos="0.1 0 0" size="0.005 .1"  quat="0.707105  0 0.707108 0 " rgba="1 0 0 0" type="cylinder" group="1"/>
        <site name="ee_y" pos="0 0.1 0" size="0.005 .1" quat="0.707105 0.707108 0 0" rgba="0 1 0 0" type="cylinder" group="1"/>
        <site name="ee_z" pos="0 0 0.1" size="0.005 .1" quat="1 0 0 0" rgba="0 0 1 0" type="cylinder" group="1"/>
        <!-- This site was added for visualization. -->
        <site name="grip_site_cylinder" pos="0 0 0" size="0.005 10" rgba="0 1 0 0.3" type="cylinder" group="1"/>
      </body>
      <body name="left_outer_knuckle" pos="0 0.035 0.059098">
        <inertial pos="0 0.021559 0.015181" quat="0.47789 0.87842 0 0" mass="0.033618" diaginertia="1.9111e-05 1.79089e-05 1.90167e-06"/>
        <joint name="drive_joint" pos="0 0 0" axis="1 0 0" limited="true" range="0 0.85"/>
        <geom type="mesh" contype="0" conaffinity="0" group="1" density="0" rgba="0.753 0.753 0.753 1" mesh="left_outer_knuckle" name="left_outer_knuckle"/>
        <geom type="mesh" rgba="0.753 0.753 0.753 1" mesh="left_outer_knuckle" name="left_outer_knuckle_collision"/>
        <body name="left_finger" pos="0 0.035465 0.042039">
          <inertial pos="0 -0.016413 0.029258" quat="0.697634 0.115353 -0.115353 0.697634" mass="0.048304" diaginertia="1.88037e-05 1.7493e-05 3.56792e-06"/>
          <joint name="left_finger_joint" pos="0 0 0" axis="-1 0 0" limited="true" range="0 0.85"/>
          <geom type="mesh" contype="0" conaffinity="0" group="1" density="0" rgba="0.753 0.753 0.753 1" mesh="left_finger" name="left_finger"/>
          <geom type="mesh" rgba="0.753 0.753 0.753 1" mesh="left_finger" name="left_finger_collision"/>
          <geom size="0.011 0.003175 0.01875" pos="0 -0.0220203 0.03242" type="box" contype="0" conaffinity="0" group="1" rgba="0.9 0.9 0.9 1" name="left_fingertip_visual" />
          <geom size="0.011 0.003175 0.01875" pos="0 -0.0220203 0.03242" type="box" group="0" rgba="0.9 0.9 0.9 1" name="left_fingertip_collision" solref="0.01 0.25" />
          <geom size="0.010 0.001 0.01675" pos="0 -0.0245203 0.03242" type="box" group="0" name="left_fingerpad_collision" />
        </body>
      </body>
      <body name="left_inner_knuckle" pos="0 0.02 0.074098">
        <inertial pos="1.86601e-06 0.0220468 0.0261335" quat="0.664139 -0.242732 0.242713 0.664146" mass="0.0230126" diaginertia="8.34216e-06 6.0949e-06 2.75601e-06"/>
        <joint name="left_inner_knuckle_joint" pos="0 0 0" axis="1 0 0" limited="true" range="0 0.85"/>
        <geom type="mesh" contype="0" conaffinity="0" group="1" density="0" rgba="0.753 0.753 0.753 1" mesh="left_inner_knuckle" name="left_inner_knuckle"/>
        <geom type="mesh" rgba="0.753 0.753 0.753 1" mesh="left_inner_knuckle" name="left_inner_knuckle_collision"/>
      </body>
      <body name="right_outer_knuckle" pos="0 -0.035 0.059098">
        <inertial pos="0 -0.021559 0.015181" quat="0.87842 0.47789 0 0" mass="0.033618" diaginertia="1.9111e-05 1.79089e-05 1.90167e-06"/>
        <joint name="right_outer_knuckle_joint" pos="0 0 0" axis="-1 0 0" limited="true" range="0 0.85"/>
        <geom type="mesh" contype="0" conaffinity="0" group="1" density="0" rgba="0.753 0.753 0.753 1" mesh="right_outer_knuckle" name="right_outer_knuckle"/>
        <geom type="mesh" rgba="0.753 0.753 0.753 1" mesh="right_outer_knuckle" name="right_outer_knuckle_collision"/>
        <body name="right_finger" pos="0 -0.035465 0.042039">
          <inertial pos="0 0.016413 0.029258" quat="0.697634 -0.115356 0.115356 0.697634" mass="0.048304" diaginertia="1.88038e-05 1.7493e-05 3.56779e-06"/>
          <joint name="right_finger_joint" pos="0 0 0" axis="1 0 0" limited="true" range="0 0.85"/>
          <geom type="mesh" contype="0" conaffinity="0" group="1" density="0" rgba="0.753 0.753 0.753 1" mesh="right_finger" name="right_finger"/>
          <geom type="mesh" rgba="0.753 0.753 0.753 1" mesh="right_finger" name="right_finger_collision"/>
          <geom size="0.011 0.003175 0.01875" pos="0 0.0220203 0.03242" type="box" contype="0" conaffinity="0" group="1" rgba="0.9 0.9 0.9 1" name="right_fingertip_visual" />
          <geom size="0.011 0.003175 0.01875" pos="0 0.0220203 0.03242" type="box" group="0" rgba="0.9 0.9 0.9 1" name="right_fingertip_collision" solref="0.01 0.25" />
          <geom size="0.010 0.001 0.01675" pos="0 0.0245203 0.03242" type="box" group="0" name="right_fingerpad_collision" />
        </body>
      </body>
      <body name="right_inner_knuckle" pos="0 -0.02 0.074098">
        <inertial pos="1.866e-06 -0.022047 0.026133" quat="0.66415 0.242702 -0.242721 0.664144" mass="0.023013" diaginertia="8.34209e-06 6.0949e-06 2.75601e-06"/>
        <joint name="right_inner_knuckle_joint" pos="0 0 0" axis="-1 0 0" limited="true" range="0 0.85"/>
        <geom type="mesh" contype="0" conaffinity="0" group="1" density="0" rgba="0.753 0.753 0.753 1" mesh="right_inner_knuckle" name="right_inner_knuckle"/>
        <geom type="mesh" rgba="0.753 0.753 0.753 1" mesh="right_inner_knuckle" name="right_inner_knuckle_collision"/>
      </body>
    </body>
  </worldbody>
  <sensor>
    <force name="force_ee" site="ft_frame"/>
    <torque name="torque_ee" site="ft_frame"/>
  </sensor>
</mujoco>
