<mujoco model="xarm6">
    <actuator>
      <!-- Physical limits of the actuator. -->
      <motor ctrllimited="true" ctrlrange="-50.0 50.0" joint="joint1" name="torq_j1"/>
      <motor ctrllimited="true" ctrlrange="-50.0 50.0" joint="joint2" name="torq_j2"/>
      <!-- <motor ctrllimited="true" ctrlrange="-32.0 32.0" joint="joint3" name="torq_j3"/> -->
      <!-- <motor ctrllimited="true" ctrlrange="-32.0 32.0" joint="joint4" name="torq_j4"/> -->
      <!-- <motor ctrllimited="true" ctrlrange="-32.0 32.0" joint="joint5" name="torq_j5"/> -->
      <motor ctrllimited="true" ctrlrange="-50.0 50.0" joint="joint3" name="torq_j3"/>
      <motor ctrllimited="true" ctrlrange="-50.0 50.0" joint="joint4" name="torq_j4"/>
      <motor ctrllimited="true" ctrlrange="-50.0 50.0" joint="joint5" name="torq_j5"/>
      <motor ctrllimited="true" ctrlrange="-20.0 20.0" joint="joint6" name="torq_j6"/>
    </actuator>
    <asset>
    <mesh name="base" file="meshes/base.stl"/>
    <mesh name="link1" file="meshes/link1.stl"/>
    <mesh name="link2" file="meshes/link2.stl"/>
    <mesh name="link3" file="meshes/link3.stl"/>
    <mesh name="link4" file="meshes/link4.stl"/>
    <mesh name="link5" file="meshes/link5.stl"/>
    <mesh name="link6" file="meshes/link6.stl"/>
  </asset>
  <worldbody>
    <body name="base" pos="0 0 0">
      <!-- robot view -->
      <camera mode="fixed" name="robotview" pos="1.0 0 0.4" quat="0.653 0.271 0.271 0.653"/>
      <inertial diaginertia="0 0 0" mass="0" pos="0 0 0"/>
      <!-- mount attached here -->
      <body name="link0" pos="0 0 0">
        <inertial pos="0 0 0.05" mass="4" diaginertia="0.4 0.4 0.4" /> <!--This is unknown-->
        <geom type="mesh" contype="0" conaffinity="0" group="1" density="0" rgba="1 1 1 1" mesh="base" name="link0_visual"/>
        <geom type="mesh" rgba="1 1 1 1" mesh="base" name="link0_collision"/>
        <body name="link1" pos="0 0 0.267">
          <inertial pos="-0.002 0.02692 -0.01332" quat="0.983139 0.180751 -0.00455228 0.0272976" mass="2.16" diaginertia="0.00539487 0.00519906 0.00281397"/>
          <joint name="joint1" pos="0 0 0" axis="0 0 1" limited="true" range="-6.28319 6.28319" damping="1" frictionloss="1"/>
          <geom type="mesh" contype="0" conaffinity="0" group="1" density="0" rgba="1 1 1 1" mesh="link1" name="link1_visual"/>
          <geom type="mesh" rgba="1 1 1 1" mesh="link1" name="link1_collision"/>
          <body name="link2" quat="0.707105 -0.707108 0 0">
            <inertial pos="0.03531 -0.21398 0.03386" quat="0.71118 0.614686 0.139936 -0.311132" mass="1.71" diaginertia="0.017867 0.017867 0.017867"/>
            <joint name="joint2" pos="0 0 0" axis="0 0 1" limited="true" range="-2.059 2.0944" damping="1" frictionloss="1"/>
            <geom type="mesh" contype="0" conaffinity="0" group="1" density="0" rgba="1 1 1 1" mesh="link2" name="link2_visual"/>
            <geom type="mesh" rgba="1 1 1 1" mesh="link2" name="link2_collision"/>
            <body name="link3" pos="0.0535 -0.2845 0">
              <inertial pos="0.06781 0.10749 0.01457" quat="0.119516 0.409082 -0.734824 0.527638" mass="1.384" diaginertia="0.004543 0.004543 0.004543"/>
              <joint name="joint3" pos="0 0 0" axis="0 0 1" limited="true" range="-3.927 0.19198" damping="1" frictionloss="1"/>
              <geom type="mesh" contype="0" conaffinity="0" group="1" density="0" rgba="1 1 1 1" mesh="link3" name="link3_visual"/>
              <geom type="mesh" rgba="1 1 1 1" mesh="link3" name="link3_collision"/>
              <body name="link4" pos="0.0775 0.3425 0" quat="0.707105 -0.707108 0 0">
                <inertial pos="-0.00021 0.02578 -0.02538" quat="0.994019 0.0752563 -0.00686804 0.0788347" mass="1.115" diaginertia="0.00440091 0.00406855 0.00103407"/>
                <joint name="joint4" pos="0 0 0" axis="0 0 1" limited="true" range="-6.28319 6.28319" damping="1" frictionloss="1"/>
                <geom type="mesh" contype="0" conaffinity="0" group="1" density="0" rgba="1 1 1 1" mesh="link4" name="link4_visual"/>
                <geom type="mesh" rgba="1 1 1 1" mesh="link4" name="link4_collision"/>
                <body name="link5" quat="0.707105 0.707108 0 0">
                  <inertial pos="0.05428 0.01781 0.00543" quat="-0.0766302 0.578118 -0.269638 0.766291" mass="1.275" diaginertia="0.00289757 0.0023276 0.000951789"/>
                  <joint name="joint5" pos="0 0 0" axis="0 0 1" limited="true" range="-1.69297 3.14159" damping="1" frictionloss="1"/>
                  <geom type="mesh" contype="0" conaffinity="0" group="1" density="0" rgba="1 1 1 1" mesh="link5" name="link5_visual"/>
                  <geom type="mesh" rgba="1 1 1 1" mesh="link5" name="link5_collision"/>
                  <body name="link6" pos="0.076 0.097 0" quat="0.707105 -0.707108 0 0">
                    <inertial pos="0 0.00064 -0.00952" quat="0 0.707107 0 0.707107" mass="0.1096" diaginertia="7.9715e-05 4.8111e-05 4.5293e-05"/>
                    <joint name="joint6" pos="0 0 0" axis="0 0 1" limited="true" range="-6.28319 6.28319" damping="1" frictionloss="1"/>
                    <geom type="mesh" contype="0" conaffinity="0" group="1" density="0" rgba="0.753 0.753 0.753 1" mesh="link6" name="link6_visual"/>
                    <geom type="mesh" rgba="0.753 0.753 0.753 1" mesh="link6" name="link6_collision"/>
                    <body name="right_hand" pos="0 0 0" quat="1 0 0 0">
                      <!-- <inertial pos="0 0 0" mass="0.5" diaginertia="0.05 0.05 0.05" /> -->
                      <site name="ee" pos="0 0 0" size="0.01 0.01 0.01" rgba="0 0 1 1" type="sphere" group="1"/>
                      <site name="ee_x" pos="0 0 0" size="0.005 .1"  quat="0.707105 0.707108 0 0 " rgba="1 0 0 0" type="cylinder" group="1"/>
                      <site name="ee_z" pos="0 0 0" size="0.005 .1" quat="0.707105 0 0 0.707108" rgba="0 0 1 0" type="cylinder" group="1"/>
                      <site name="ee_y" pos="0 0 0" size="0.005 .1" quat="0.707105 0 0.707108 0 " rgba="0 1 0 0" type="cylinder" group="1"/>
                      <!-- This camera points out from the eef. -->
                      <camera mode="fixed" name="eye_in_hand" pos="0.05 0 0" quat="0 0.707108 0.707108 0" fovy="75"/>
                      <!-- to add gripper -->
                    </body>
                  </body>
                </body>
              </body>
            </body>
          </body>
        </body>
      </body>
    </body>
  </worldbody>
</mujoco>
